<!-- <?xml version="1.0"?>
<robot name="exodus_arm" xmlns:xacro="http://www.ros.org/wiki/xacro">

  <!-- TODO: Add actual URDF description here omri and tomer this is a structure example -->

  
  <xacro:arg name="use_fake_hardware" default="false"/>
  <xacro:arg name="can_interface" default="slcan0"/>
  
  <!-- Include ros2_control xacro -->
  <xacro:include filename="$(find arm_description)/urdf/arm.ros2_control.xacro"/>
  
  <!-- Invoke the ros2_control macro -->
  <xacro:arm_ros2_control 
    name="ExodusArmSystem" 
    use_fake_hardware="$(arg use_fake_hardware)"
    can_interface="$(arg can_interface)"/>

  <!-- Placeholder links and joints -->
  <!-- TODO: Replace with actual robot geometry -->
  
  <link name="base_link">
    <visual>
      <geometry>
        <box size="0.1 0.1 0.1"/>
      </geometry>
      <origin xyz="0 0 0.05" rpy="0 0 0"/>
      <material name="grey">
        <color rgba="0.5 0.5 0.5 1.0"/>
      </material>
    </visual>
    <collision>
      <geometry>
        <box size="0.1 0.1 0.1"/>
      </geometry>
      <origin xyz="0 0 0.05" rpy="0 0 0"/>
    </collision>
  </link>

  <link name="link1">
    <visual>
      <geometry>
        <cylinder length="0.2" radius="0.03"/>
      </geometry>
      <origin xyz="0 0 0.1" rpy="0 0 0"/>
      <material name="blue">
        <color rgba="0.0 0.0 0.8 1.0"/>
      </material>
    </visual>
    <collision>
      <geometry>
        <cylinder length="0.2" radius="0.03"/>
      </geometry>
      <origin xyz="0 0 0.1" rpy="0 0 0"/>
    </collision>
  </link>

  <joint name="joint1" type="revolute">
    <parent link="base_link"/>
    <child link="link1"/>
    <origin xyz="0 0 0.1" rpy="0 0 0"/>
    <axis xyz="0 0 1"/>
    <limit lower="-3.14" upper="3.14" effort="10.0" velocity="7.5"/>
  </joint>

  <link name="link2">
    <visual>
      <geometry>
        <cylinder length="0.2" radius="0.025"/>
      </geometry>
      <origin xyz="0 0 0.1" rpy="0 0 0"/>
      <material name="green">
        <color rgba="0.0 0.8 0.0 1.0"/>
      </material>
    </visual>
    <collision>
      <geometry>
        <cylinder length="0.2" radius="0.025"/>
      </geometry>
      <origin xyz="0 0 0.1" rpy="0 0 0"/>
    </collision>
  </link>

  <joint name="joint2" type="revolute">
    <parent link="link1"/>
    <child link="link2"/>
    <origin xyz="0 0 0.2" rpy="0 0 0"/>
    <axis xyz="0 1 0"/>
    <limit lower="-1.57" upper="1.57" effort="15.0" velocity="12.0"/>
  </joint>

  <link name="link3">
    <visual>
      <geometry>
        <cylinder length="0.15" radius="0.025"/>
      </geometry>
      <origin xyz="0 0 0.075" rpy="0 0 0"/>
      <material name="green"/>
    </visual>
    <collision>
      <geometry>
        <cylinder length="0.15" radius="0.025"/>
      </geometry>
      <origin xyz="0 0 0.075" rpy="0 0 0"/>
    </collision>
  </link>

  <joint name="joint3" type="revolute">
    <parent link="link2"/>
    <child link="link3"/>
    <origin xyz="0 0 0.2" rpy="0 0 0"/>
    <axis xyz="0 1 0"/>
    <limit lower="-1.57" upper="1.57" effort="15.0" velocity="12.0"/>
  </joint>

  <link name="link4">
    <visual>
      <geometry>
        <cylinder length="0.1" radius="0.02"/>
      </geometry>
      <origin xyz="0 0 0.05" rpy="0 0 0"/>
      <material name="red">
        <color rgba="0.8 0.0 0.0 1.0"/>
      </material>
    </visual>
    <collision>
      <geometry>
        <cylinder length="0.1" radius="0.02"/>
      </geometry>
      <origin xyz="0 0 0.05" rpy="0 0 0"/>
    </collision>
  </link>

  <joint name="joint4" type="revolute">
    <parent link="link3"/>
    <child link="link4"/>
    <origin xyz="0 0 0.15" rpy="0 0 0"/>
    <axis xyz="0 0 1"/>
    <limit lower="-3.14" upper="3.14" effort="8.0" velocity="2.5"/>
  </joint>

  <link name="link5">
    <visual>
      <geometry>
        <cylinder length="0.08" radius="0.015"/>
      </geometry>
      <origin xyz="0 0 0.04" rpy="0 0 0"/>
      <material name="yellow">
        <color rgba="0.8 0.8 0.0 1.0"/>
      </material>
    </visual>
    <collision>
      <geometry>
        <cylinder length="0.08" radius="0.015"/>
      </geometry>
      <origin xyz="0 0 0.04" rpy="0 0 0"/>
    </collision>
  </link>

  <joint name="joint5" type="revolute">
    <parent link="link4"/>
    <child link="link5"/>
    <origin xyz="0 0 0.1" rpy="0 0 0"/>
    <axis xyz="0 1 0"/>
    <limit lower="-1.57" upper="1.57" effort="5.0" velocity="17.5"/>
  </joint>

  <!-- End effector link -->
  <link name="tool0"/>
  
  <joint name="joint5_to_tool0" type="fixed">
    <parent link="link5"/>
    <child link="tool0"/>
    <origin xyz="0 0 0.08" rpy="0 0 0"/>
  </joint>

</robot>
 -->
